2019-03-03 17:21:28,896 ERROR Exception on /user/lauren [GET] [in /home/ben/python projects/microblog/venv/lib/python3.6/site-packages/flask/app.py:1761]
Traceback (most recent call last):
  File "/home/ben/python projects/microblog/venv/lib/python3.6/site-packages/sqlalchemy/engine/base.py", line 1236, in _execute_context
    cursor, statement, parameters, context
  File "/home/ben/python projects/microblog/venv/lib/python3.6/site-packages/sqlalchemy/engine/default.py", line 536, in do_execute
    cursor.execute(statement, parameters)
sqlite3.OperationalError: no such table: followers

The above exception was the direct cause of the following exception:

Traceback (most recent call last):
  File "/home/ben/python projects/microblog/venv/lib/python3.6/site-packages/flask/app.py", line 2292, in wsgi_app
    response = self.full_dispatch_request()
  File "/home/ben/python projects/microblog/venv/lib/python3.6/site-packages/flask/app.py", line 1815, in full_dispatch_request
    rv = self.handle_user_exception(e)
  File "/home/ben/python projects/microblog/venv/lib/python3.6/site-packages/flask/app.py", line 1718, in handle_user_exception
    reraise(exc_type, exc_value, tb)
  File "/home/ben/python projects/microblog/venv/lib/python3.6/site-packages/flask/_compat.py", line 35, in reraise
    raise value
  File "/home/ben/python projects/microblog/venv/lib/python3.6/site-packages/flask/app.py", line 1813, in full_dispatch_request
    rv = self.dispatch_request()
  File "/home/ben/python projects/microblog/venv/lib/python3.6/site-packages/flask/app.py", line 1799, in dispatch_request
    return self.view_functions[rule.endpoint](**req.view_args)
  File "/home/ben/python projects/microblog/venv/lib/python3.6/site-packages/flask_login/utils.py", line 261, in decorated_view
    return func(*args, **kwargs)
  File "/home/ben/python projects/microblog/app/routes.py", line 83, in user
    return render_template('user.html', user = user, posts = posts)
  File "/home/ben/python projects/microblog/venv/lib/python3.6/site-packages/flask/templating.py", line 135, in render_template
    context, ctx.app)
  File "/home/ben/python projects/microblog/venv/lib/python3.6/site-packages/flask/templating.py", line 117, in _render
    rv = template.render(context)
  File "/home/ben/python projects/microblog/venv/lib/python3.6/site-packages/jinja2/asyncsupport.py", line 76, in render
    return original_render(self, *args, **kwargs)
  File "/home/ben/python projects/microblog/venv/lib/python3.6/site-packages/jinja2/environment.py", line 1008, in render
    return self.environment.handle_exception(exc_info, True)
  File "/home/ben/python projects/microblog/venv/lib/python3.6/site-packages/jinja2/environment.py", line 780, in handle_exception
    reraise(exc_type, exc_value, tb)
  File "/home/ben/python projects/microblog/venv/lib/python3.6/site-packages/jinja2/_compat.py", line 37, in reraise
    raise value.with_traceback(tb)
  File "/home/ben/python projects/microblog/app/templates/user.html", line 1, in top-level template code
    {% extends "base.html" %}
  File "/home/ben/python projects/microblog/app/templates/base.html", line 30, in top-level template code
    {% block content %}{% endblock %}
  File "/home/ben/python projects/microblog/app/templates/user.html", line 11, in block "content"
    <p>{{ user.followers.count() }} followers, {{ user.followed.count() }} following.</p>
  File "/home/ben/python projects/microblog/venv/lib/python3.6/site-packages/sqlalchemy/orm/dynamic.py", line 323, in count
    return self._clone(sess).count()
  File "/home/ben/python projects/microblog/venv/lib/python3.6/site-packages/sqlalchemy/orm/query.py", line 3318, in count
    return self.from_self(col).scalar()
  File "/home/ben/python projects/microblog/venv/lib/python3.6/site-packages/sqlalchemy/orm/query.py", line 3069, in scalar
    ret = self.one()
  File "/home/ben/python projects/microblog/venv/lib/python3.6/site-packages/sqlalchemy/orm/query.py", line 3039, in one
    ret = self.one_or_none()
  File "/home/ben/python projects/microblog/venv/lib/python3.6/site-packages/sqlalchemy/orm/query.py", line 3008, in one_or_none
    ret = list(self)
  File "/home/ben/python projects/microblog/venv/lib/python3.6/site-packages/sqlalchemy/orm/query.py", line 3081, in __iter__
    return self._execute_and_instances(context)
  File "/home/ben/python projects/microblog/venv/lib/python3.6/site-packages/sqlalchemy/orm/query.py", line 3106, in _execute_and_instances
    result = conn.execute(querycontext.statement, self._params)
  File "/home/ben/python projects/microblog/venv/lib/python3.6/site-packages/sqlalchemy/engine/base.py", line 980, in execute
    return meth(self, multiparams, params)
  File "/home/ben/python projects/microblog/venv/lib/python3.6/site-packages/sqlalchemy/sql/elements.py", line 273, in _execute_on_connection
    return connection._execute_clauseelement(self, multiparams, params)
  File "/home/ben/python projects/microblog/venv/lib/python3.6/site-packages/sqlalchemy/engine/base.py", line 1099, in _execute_clauseelement
    distilled_params,
  File "/home/ben/python projects/microblog/venv/lib/python3.6/site-packages/sqlalchemy/engine/base.py", line 1240, in _execute_context
    e, statement, parameters, cursor, context
  File "/home/ben/python projects/microblog/venv/lib/python3.6/site-packages/sqlalchemy/engine/base.py", line 1458, in _handle_dbapi_exception
    util.raise_from_cause(sqlalchemy_exception, exc_info)
  File "/home/ben/python projects/microblog/venv/lib/python3.6/site-packages/sqlalchemy/util/compat.py", line 296, in raise_from_cause
    reraise(type(exception), exception, tb=exc_tb, cause=cause)
  File "/home/ben/python projects/microblog/venv/lib/python3.6/site-packages/sqlalchemy/util/compat.py", line 276, in reraise
    raise value.with_traceback(tb)
  File "/home/ben/python projects/microblog/venv/lib/python3.6/site-packages/sqlalchemy/engine/base.py", line 1236, in _execute_context
    cursor, statement, parameters, context
  File "/home/ben/python projects/microblog/venv/lib/python3.6/site-packages/sqlalchemy/engine/default.py", line 536, in do_execute
    cursor.execute(statement, parameters)
sqlalchemy.exc.OperationalError: (sqlite3.OperationalError) no such table: followers [SQL: 'SELECT count(*) AS count_1 \nFROM (SELECT user.id AS user_id, user.username AS user_username, user.email AS user_email, user.password_hash AS user_password_hash, user.about_me AS user_about_me, user.last_seen AS user_last_seen \nFROM user, followers \nWHERE followers.followed_id = ? AND followers.follower_id = user.id) AS anon_1'] [parameters: (3,)] (Background on this error at: http://sqlalche.me/e/e3q8)
2019-03-03 17:31:08,087 INFO Microblog startup [in /home/ben/python projects/microblog/app/__init__.py:42]
2019-03-03 17:35:14,554 INFO Microblog startup [in /home/ben/python projects/microblog/app/__init__.py:42]
2019-03-03 17:35:31,102 INFO Microblog startup [in /home/ben/python projects/microblog/app/__init__.py:42]
2019-03-03 17:35:37,505 INFO Microblog startup [in /home/ben/python projects/microblog/app/__init__.py:42]
